<robot xmlns:xacro="http://www.ros.org/wiki/xacro">
  <xacro:macro name="shadowarm_handsupport_motor" params="parent">
    <link name="shadowarm_handsupport">
      <inertial>
        <origin xyz="0 0 0" rpy="0 0 0" />
        <mass value="0.75" />
        <inertia ixx="0.00086" ixy="0.0" ixz="0.0" iyy="0.00086"
        iyz="0.0" izz="0.0017" />
      </inertial>
      <visual>
        <origin xyz="0 0 -0.04" rpy="0 0 0" />
        <geometry name="shadowarm_handsupport_visual">
          <mesh filename="package://sr_description/arm/model/elbow_rotate_motor.dae"
          scale="0.001 0.001 0.001" />
        </geometry>
        <material name="LightGrey" />
      </visual>
      <collision>
        <origin xyz="0 0 -0.04" rpy="0 0 0" />
        <geometry name="shadowarm_handsupport_visual">
          <mesh filename="package://sr_description/arm/model/elbow_rotate_motor.dae"
          scale="0.001 0.001 0.001" />
        </geometry>
      </collision>
    </link>
    <joint name="ElbowJRotate" type="revolute">
      <parent link="${parent}" />
      <child link="shadowarm_handsupport" />
      <origin xyz="0.08 0 0.125" rpy="0.0 0 0" />
      <axis xyz="0 0 -1" />
      <limit lower="-${M_PI/2}" upper="${M_PI/2}" effort="30"
      velocity="1.0" />
      <dynamics damping="5.5" />
    </joint>
  </xacro:macro>
</robot>
