<?xml version="1.0" ?>
<!-- =================================================================================== -->
<!-- |    This document was autogenerated by xacro from arm_itself.urdf.xacro          | -->
<!-- |    EDITING THIS FILE BY HAND IS NOT RECOMMENDED                                 | -->
<!-- =================================================================================== -->
<robot name="full_arm_motor" xmlns:controller="http://playerstage.sourceforge.net/gazebo/xmlschema/#controller" xmlns:interface="http://playerstage.sourceforge.net/gazebo/xmlschema/#interface" xmlns:sensor="http://playerstage.sourceforge.net/gazebo/xmlschema/#sensor" xmlns:xacro="http://www.ros.org/wiki/xacro">
  <link name="base_link"/>
  <joint name="arm_to_world_fixed" type="fixed">
    <parent link="base_link"/>
    <child link="shadowarm_base"/>
    <origin rpy="0 0 0" xyz="0 0 1.0"/>
  </joint>
  <link name="shadowarm_base">
    <inertial>
      <origin rpy="0 0 0" xyz="0 0 0"/>
      <mass value="0.4"/>
      <inertia ixx="0.00071" ixy="0.0" ixz="0.0" iyy="0.00071" iyz="0.0" izz="0.0014"/>
    </inertial>
    <visual>
      <origin rpy="0 0 0" xyz="0 0 0"/>
      <geometry name="shadowarm_base_visual">
        <mesh filename="package://sr_description/arm/model/arm_base.dae" scale="0.001 0.001 0.001"/>
      </geometry>
      <material name="LightGrey"/>
    </visual>
    <collision>
      <origin rpy="0 0 0" xyz="0 0 0"/>
      <geometry name="shadowarm_base_visual">
        <mesh filename="package://sr_description/arm/model/arm_base.dae" scale="0.001 0.001 0.001"/>
      </geometry>
    </collision>
  </link>
  <link name="shadowarm_trunk">
    <inertial>
      <origin rpy="0 0 0" xyz="0 0 0.26525"/>
      <mass value="10"/>
      <inertia ixx="0.298" ixy="0.0" ixz="0.0" iyy="0.298" iyz="0.0" izz="0.0361"/>
    </inertial>
    <visual>
      <origin rpy="0 0 0" xyz="0 0 0.005"/>
      <geometry name="shadowarm_trunk_visual">
        <mesh filename="package://sr_description/arm/model/arm_trunk.dae" scale="0.001 0.001 0.001"/>
      </geometry>
      <material name="Grey"/>
    </visual>
    <collision>
      <origin rpy="0 0 0" xyz="0 0 0.005"/>
      <geometry name="shadowarm_trunk_visual">
        <mesh filename="package://sr_description/arm/model/arm_trunk.dae" scale="0.001 0.001 0.001"/>
      </geometry>
    </collision>
  </link>
  <joint name="ShoulderJRotate" type="revolute">
    <parent link="shadowarm_base"/>
    <child link="shadowarm_trunk"/>
    <origin rpy="0.0 0.0 0.0" xyz="0 0 0.01"/>
    <axis xyz="0 0 1"/>
    <limit effort="70" lower="-0.785398163397" upper="1.57079632679" velocity="1.0"/>
    <dynamics damping="5.5"/>
  </joint>
  <link name="shadowarm_upperarm">
    <inertial>
      <origin rpy="0 0 0" xyz="0 0 0.1845"/>
      <mass value="2"/>
      <inertia ixx="0.044" ixy="0.0" ixz="0.0" iyy="0.044" iyz="0.0" izz="0.0056"/>
    </inertial>
    <visual>
      <origin rpy="0 0 0" xyz="0 0.067 0"/>
      <geometry name="shadowarm_upperarm_visual">
        <mesh filename="package://sr_description/arm/model/upper_arm.dae" scale="0.001 0.001 0.001"/>
      </geometry>
      <material name="Grey"/>
    </visual>
    <collision>
      <origin rpy="0 0 0" xyz="0 0.067 0"/>
      <geometry name="shadowarm_upperarm_visual">
        <mesh filename="package://sr_description/arm/model/upper_arm.dae" scale="0.001 0.001 0.001"/>
      </geometry>
    </collision>
  </link>
  <joint name="ShoulderJSwing" type="revolute">
    <parent link="shadowarm_trunk"/>
    <child link="shadowarm_upperarm"/>
    <origin rpy="0 -3.14159265359 0.0" xyz="0 -0.134 0.5305"/>
    <!-- yaw=-0.026 -->
    <axis xyz="0 -1 0"/>
    <limit effort="100" lower="0" upper="1.57079632679" velocity="1.0"/>
    <dynamics damping="5.3"/>
  </joint>
  <link name="shadowarm_lowerarm">
    <inertial>
      <origin rpy="0 0 0" xyz="0.08 0 0.0625"/>
      <mass value="1.7"/>
      <inertia ixx="0.0016" ixy="0.0" ixz="0.0" iyy="0.0016" iyz="0.0" izz="0.0018"/>
    </inertial>
    <visual>
      <origin rpy="0 0 0" xyz="0.03 0 0.036"/>
      <geometry name="shadowarm_lowerarm_visual">
        <mesh filename="package://sr_description/arm/model/elbow_flex.dae" scale="0.001 0.001 0.001"/>
      </geometry>
      <material name="Grey"/>
    </visual>
    <collision>
      <origin rpy="0 0 0" xyz="0.03 0 0.036"/>
      <geometry name="shadowarm_lowerarm_visual">
        <mesh filename="package://sr_description/arm/model/elbow_flex.dae" scale="0.001 0.001 0.001"/>
      </geometry>
    </collision>
  </link>
  <joint name="ElbowJSwing" type="revolute">
    <parent link="shadowarm_upperarm"/>
    <child link="shadowarm_lowerarm"/>
    <origin rpy="0 0 0" xyz="0 0 0.369"/>
    <axis xyz="0 -1 0"/>
    <limit effort="50" lower="-0.52" upper="2.09439510239" velocity="1.0"/>
    <dynamics damping="5.5"/>
  </joint>
  <link name="shadowarm_handsupport">
    <inertial>
      <origin rpy="0 0 0" xyz="0 0 0"/>
      <mass value="0.75"/>
      <inertia ixx="0.00086" ixy="0.0" ixz="0.0" iyy="0.00086" iyz="0.0" izz="0.0017"/>
    </inertial>
    <visual>
      <origin rpy="0 0 0" xyz="0 0 -0.04"/>
      <geometry name="shadowarm_handsupport_visual">
        <mesh filename="package://sr_description/arm/model/elbow_rotate_motor.dae" scale="0.001 0.001 0.001"/>
      </geometry>
      <material name="LightGrey"/>
    </visual>
    <collision>
      <origin rpy="0 0 0" xyz="0 0 -0.04"/>
      <geometry name="shadowarm_handsupport_visual">
        <mesh filename="package://sr_description/arm/model/elbow_rotate_motor.dae" scale="0.001 0.001 0.001"/>
      </geometry>
    </collision>
  </link>
  <joint name="ElbowJRotate" type="revolute">
    <parent link="shadowarm_lowerarm"/>
    <child link="shadowarm_handsupport"/>
    <origin rpy="0.0 0 0" xyz="0.08 0 0.125"/>
    <axis xyz="0 0 -1"/>
    <limit effort="30" lower="-1.57079632679" upper="1.57079632679" velocity="1.0"/>
    <dynamics damping="5.5"/>
  </joint>
</robot>

